import traceback
from functools import wraps

def handle_errors(func):
    @wraps(func)
    def wrapper(*args, **kwargs):
        try:
            return func(*args, **kwargs)
        except Exception as e:
            print(f"An error occurred in {func.__name__}: {e}")
            traceback.print_exc() 
            return None 

    return wrapper
